Workbook

Sheet INEGI_DENUE_24062016
A1: ID | B1: Nombre de la Unidad Economica | C1: Razon social | D1: Codigo de la clase de actividad SCIAN | E1: Nombre de clase de la actividad | F1: Automotriz | G1: Descripcion estrato personal ocupado | H1: Tipo de vialidad | I1: Nombre de la vialidad | J1: Tipo de entre vialidad 1 | K1: Nombre de entre vialidad 1 | L1: Tipo de entre vialidad 2 | M1: Nombre de entre vialidad 2 | N1: Tipo de entre vialidad 3 | O1: Nombre de entre vialidad 3 | P1: NÃºmero exterior o kilometro | Q1: Letra exterior | R1: Edificio | S1: Edificio Piso | T1: NÃºmero interior | U1: Letra interior | V1: Tipo de asentamiento humano | W1: Nombre de asentamiento humano | X1: Tipo centro comercial | Y1: Corredor industrial, centro comercial o mercado pÃºblico | Z1: NÃºmero de local | AA1: Codigo Postal | AB1: Clave entidad | AC1: Entidad federativa | AD1: Clave municipio | AE1: Municipio | AF1: Clave localidad | AG1: Localidad | AH1: Area geoestadistica basica | AI1: Manzana | AJ1: NÃºmero de telEfono | AK1: Correo electronico | AL1: Sitio en Internet | AM1: Tipo de establecimiento | AN1: Latitud | AO1: Longitud | AP1: Fecha de incorporacion al DENUE
A2: 1357680 | B2: AGUA HYDRA NATURA | D2: 312112 | E2: Purificacion y embotellado de agua | F2: =VLOOKUP(E2,Sheet1!$B$2:$C$78,2,0) -> 0 | G2: 11 a 30 personas | H2: AVENIDA | I2: CONSTITUYENTES | J2: CALLE | K2: HENRRY DUNANT | L2: PRIVADA | M2: ALHELÃES | N2: CALLE | O2: ALHELÃES | P2: 702 | Q2: A | V2: COLONIA | W2: ROSALINDA II | AA2: 38060 | AB2: 11 | AC2: GUANAJUATO | AD2: 7 | AE2: CELAYA | AF2: 1 | AG2: Celaya | AH2: 1690 | AI2: 24 | AJ2: 4616151111 | AM2: Fijo | AN2: 20.518535 | AO2: -100.83979 | AP2: 40360
A3: 6329532 | B3: ARNIME, S.A. DE C.V. | C3: ARNIME, S.A. DE C.V. | D3: 311422 | E3: Conservacion de frutas y verduras por procesos distintos a la congelacion y la deshidratacion | F3: =VLOOKUP(E3,Sheet1!$B$2:$C$78,2,0) -> 0 | G3: 101 a 250 personas | H3: CARRETERA | I3: CARRETERA FEDERAL LIBRE 51 CELAYA - VILLAGRÃN KILOMETROS 4200 | J3: CALLE | K3: NINGUNO | L3: CALLE | M3: NINGUNO | O3: NINGUNO | P3: 0 | Q3: SN | T3: 0 | V3: FRACCIONAMIENTO | W3: SANTA ELENA | AA3: 38110 | AB3: 11 | AC3: GUANAJUATO | AD3: 7 | AE3: CELAYA | AF3: 674 | AG3: Ninguno [Balneario] | AH3: 71 | AI3: 800 | AJ3: 4616110088 | AK3: PERSONALARNIME@GMAIL.COM | AL3: WWW.ARNIME.COM | AM3: Fijo | AN3: 20.497808 | AO3: -100.84001 | AP3: 41974
A4: 6331220 | B4: BODEGA DE DISTRIBUCION DE HUEVO | C4: BACHOCO SA DE CV | D4: 311110 | E4: Elaboracion de alimentos para animales | F4: =VLOOKUP(E4,Sheet1!$B$2:$C$78,2,0) -> 0 | G4: 11 a 30 personas | H4: CALLE | I4: CONCEPCIÃ“N BÃ‰ISTEGUI | J4: CALLE | K4: CONCEPCIÃ“N BÃ‰ISTEGUI | L4: CALLE | M4: EJE NOR-PONIENTE | N4: CALLE | O4: NINGUNO | P4: 0 | Q4: SN | T4: 0 | V4: COLONIA | W4: NINGUNO | AA4: 38020 | AB4: 11 | AC4: GUANAJUATO | AD4: 7 | AE4: CELAYA | AF4: 1 | AG4: Celaya | AH4: 724 | AI4: 11 | AJ4: 4611567983 | AM4: Fijo | AN4: 20.519849 | AO4: -100.84993 | AP4: 40360
A5: 1349181 | B5: CAJETAS Y DULCES LA TRADICIONAL | D5: 311340 | E5: Elaboracion de dulces, chicles y productos de confiteria que no sean de chocolate | F5: =VLOOKUP(E5,Sheet1!$B$2:$C$78,2,0) -> 0 | G5: 11 a 30 personas | H5: AVENIDA | I5: LICENCIADO BENITO JUÃREZ | J5: CALLE | K5: NICOLÃS BRAVO | L5: BOULEVARD | M5: ADOLFO LÃ“PEZ MATEOS | N5: CALLE | O5: ZARAGOZA | P5: 109 | T5: 111 | V5: COLONIA | W5: CENTRO | AA5: 38000 | AB5: 11 | AC5: GUANAJUATO | AD5: 7 | AE5: CELAYA | AF5: 1 | AG5: Celaya | AH5: 156 | AI5: 29 | AJ5: 4616128706 | AM5: Fijo | AN5: 20.520609 | AO5: -100.81527 | AP5: 40360
A6: 1244351 | B6: CHAPERM, S. DE R.L. DE C.V. | C6: CHAPERM, S. DE R.L. DE C.V. | D6: 315229 | E6: Confeccion en serie de otra ropa exterior de materiales textiles | F6: =VLOOKUP(E6,Sheet1!$B$2:$C$78,2,0) -> 0 | G6: 11 a 30 personas | H6: PRIVADA | I6: DOCTOR FRANCISCO PAREDES | J6: CALLE | K6: MARIANO ABASOLO | L6: AVENIDA | M6: PROFESOR FRANCISCO JUÃREZ | N6: CALLE | O6: ALBINO GARCÃA | P6: 103 | V6: COLONIA | W6: TIERRAS NEGRAS | AA6: 38048 | AB6: 11 | AC6: GUANAJUATO | AD6: 7 | AE6: CELAYA | AF6: 1 | AG6: Celaya | AH6: 137 | AI6: 5 | AM6: Fijo | AN6: 20.524433 | AO6: -100.82401 | AP6: 41974
A7: 1347802 | B7: COMERCIAL DEL CENTRO LUCCA | C7: COMERCIAL DEL CENTRO LUCCA, S.A. DE C.V. | D7: 315223 | E7: Confeccion en serie de uniformes | F7: =VLOOKUP(E7,Sheet1!$B$2:$C$78,2,0) -> 0 | G7: 11 a 30 personas | H7: CALLE | I7: GENERAL ORTEGA | J7: CALLE | K7: GENERAL E. ORTEGA | L7: ANDADOR | M7: DE NAYARIT | N7: ANDADOR | O7: DE NAYARIT | P7: 213 | Q7: A | V7: COLONIA | W7: ALAMEDA | AA7: 38050 | AB7: 11 | AC7: GUANAJUATO | AD7: 7 | AE7: CELAYA | AF7: 1 | AG7: Celaya | AH7: 1239 | AI7: 33 | AJ7: 4616129144 | AM7: Fijo | AN7: 20.532426 | AO7: -100.80534 | AP7: 40360
A8: 6313302 | B8: COMPANIA MANUFACTURA ASTURIAS, S.A. DE C.V. | C8: COMPAÃ‘ÃA MANUFACTURA ASTURIAS, S.A. DE C.V. | D8: 311222 | E8: Elaboracion de aceites y grasas vegetales comestibles | F8: =VLOOKUP(E8,Sheet1!$B$2:$C$78,2,0) -> 0 | G8: 101 a 250 personas | I8: CARRETERA ESTATAL LIBRE CELAYA - SAN MIGUEL DE ALLENDE KILÃ“METRO 9 | K8: NINGUNO | M8: NINGUNO | O8: NINGUNO | P8: 0 | Q8: SN | T8: 0 | W8: SAN ISIDRO DE LA CONCEPCIÃ“N | AA8: 38104 | AB8: 11 | AC8: GUANAJUATO | AD8: 7 | AE8: CELAYA | AF8: 7002 | AG8: Localidad economica | AH8: 14 | AI8: 800 | AJ8: 4616188960 | AK8: R.GALLARDO@LASTUR.COM.MX | AM8: Fijo | AN8: 20.635278 | AO8: -100.785 | AP8: 40360
A9: 1245685 | B9: CONFECCIONES MAYRA | D9: 315192 | E9: Fabricacion de ropa exterior de tejido de punto | F9: =VLOOKUP(E9,Sheet1!$B$2:$C$78,2,0) -> 0 | G9: 11 a 30 personas | H9: PRIVADA | I9: LOS AZTECAS | J9: CALLE | K9: LEANDRO VALLE | L9: CALLE | M9: ABASOLO | N9: CALLE | O9: MARIANO JIMÃ‰NEZ | P9: 12 | V9: COLONIA | W9: MARIANO JIMÃ‰NEZ | AA9: 38048 | AB9: 11 | AC9: GUANAJUATO | AD9: 7 | AE9: CELAYA | AF9: 1 | AG9: Celaya | AH9: 103 | AI9: 30 | AJ9: 4616137006 | AK9: CONFECCIONESMAYRA@OTMAIL.COM | AM9: Fijo | AN9: 20.528351 | AO9: -100.82299 | AP9: 41974
A10: 1242056 | B10: CUERITOS E INCURTIDOS DEL BAJÃO | D10: 311910 | E10: Elaboracion de botanas | F10: =VLOOKUP(E10,Sheet1!$B$2:$C$78,2,0) -> 0 | G10: 11 a 30 personas | H10: PRIVADA | I10: SANTA CECILIA | J10: AVENIDA | K10: CONSTITUYENTES | L10: PRIVADA | M10: PRIMERA DE LÃZARO CÃRDENAS DEL RÃO | N10: AVENIDA | O10: CONSTITUYENTES | P10: 0 | Q10: SN | V10: COLONIA | W10: TIERRA BLANCA | AA10: 38090 | AB10: 11 | AC10: GUANAJUATO | AD10: 7 | AE10: CELAYA | AF10: 1 | AG10: Celaya | AH10: 1525 | AI10: 30 | AJ10: 4611319146 | AM10: Fijo | AN10: 20.508818 | AO10: -100.8149 | AP10: 41974
A11: 1244387 | B11: DOMINO'S PIZZA | C11: OPERADORA Y PROCESADORA DE PRODUCTOS DE PANIFICACIÃ“N, S.A. DE C.V. | D11: 311812 | E11: Panificacion tradicional | F11: =VLOOKUP(E11,Sheet1!$B$2:$C$78,2,0) -> 0 | G11: 11 a 30 personas | H11: BOULEVARD | I11: ADOLFO LÃ“PEZ MATEOS | J11: CALLE | K11: PALMAS | L11: AVENIDA | M11: 2 DE ABRIL | N11: CALLE | O11: JOSÃ‰ MARÃA MORELOS | P11: 0 | Q11: SN | V11: COLONIA | W11: CENTRO | AA11: 38000 | AB11: 11 | AC11: GUANAJUATO | AD11: 7 | AE11: CELAYA | AF11: 1 | AG11: Celaya | AH11: 018A | AI11: 12 | AJ11: 461617220 | AK11: 11349@DOMINOS.COM.MX | AL11: WWW.DOMINOS.COM.MX | AM11: Fijo | AN11: 20.520025 | AO11: -100.80021 | AP11: 41974
A12: 1348892 | B12: DON PASTEL | C12: DON PASTEL, S.A. DE C.V. | D12: 311812 | E12: Panificacion tradicional | F12: =VLOOKUP(E12,Sheet1!$B$2:$C$78,2,0) -> 0 | G12: 11 a 30 personas | H12: CALLE | I12: AGUILAR Y MAYA | J12: CALLE | K12: GUADALUPE | L12: CALLE | M12: ÃLVARO OBREGÃ“N | N12: CALLE | O12: NARCISO MENDOZA | P12: 121 | S12: PLANTA BAJA | V12: COLONIA | W12: ALAMEDA | AA12: 38050 | AB12: 11 | AC12: GUANAJUATO | AD12: 7 | AE12: CELAYA | AF12: 1 | AG12: Celaya | AH12: 156 | AI12: 26 | AJ12: 4616121511 | AM12: Fijo | AN12: 20.528161 | AO12: -100.81223 | AP12: 40360
A13: 1346633 | B13: ELABORACIÃ“N Y DISTRIBUCIÃ“N DE CHORIZO SIN NOMBRE | D13: 311613 | E13: Preparacion de embutidos y otras conservas de carne de ganado, aves y otros animales comestibles | F13: =VLOOKUP(E13,Sheet1!$B$2:$C$78,2,0) -> 0 | G13: 11 a 30 personas | H13: CALLE | I13: VIOLETA | J13: CALLE | K13: FRESNO | L13: CALLE | M13: PINO | N13: CALLE | O13: ROSA | P13: 404 | Q13: A | V13: COLONIA | W13: LINDAVISTA | AA13: 38010 | AB13: 11 | AC13: GUANAJUATO | AD13: 7 | AE13: CELAYA | AF13: 1 | AG13: Celaya | AH13: 423 | AI13: 3 | AJ13: 4616116506 | AM13: Fijo | AN13: 20.543265 | AO13: -100.82396 | AP13: 40360
A14: 1348457 | B14: EMPACADORA JB | C14: PRODUCTOS Y CARNES FRÃAS DE CELAYA JB, S.A. | D14: 311613 | E14: Preparacion de embutidos y otras conservas de carne de ganado, aves y otros animales comestibles | F14: =VLOOKUP(E14,Sheet1!$B$2:$C$78,2,0) -> 0 | G14: 11 a 30 personas | H14: AVENIDA | I14: MIGUEL HIDALGO | J14: CALLE | K14: MARIANO ABASOLO | L14: CALLE | M14: LEANDRO VALLE | N14: CALLE | O14: ANDRÃ‰S QUINATANA ROO | P14: 619 | V14: COLONIA | W14: CENTRO | AA14: 38000 | AB14: 11 | AC14: GUANAJUATO | AD14: 7 | AE14: CELAYA | AF14: 1 | AG14: Celaya | AH14: 137 | AI14: 3 | AJ14: 4616123307 | AK14: EMPACADORAJB@GMAIL.COM | AM14: Fijo | AN14: 20.521347 | AO14: -100.82115 | AP14: 40360
A15: 1245144 | B15: EMPANADAS LA TÃA GUILLE | D15: 311812 | E15: Panificacion tradicional | F15: =VLOOKUP(E15,Sheet1!$B$2:$C$78,2,0) -> 0 | G15: 11 a 30 personas | H15: CALLE | I15: GUADALUPE | J15: CALLE | K15: FRANCISCO I. MADERO | L15: CALLE | M15: 5 DE MAYO | N15: CALLE | O15: ÃLVARO OBREGÃ“N | P15: 0 | Q15: SN | V15: COLONIA | W15: CENTRO | AA15: 38000 | AB15: 11 | AC15: GUANAJUATO | AD15: 7 | AE15: CELAYA | AF15: 1 | AG15: Celaya | AH15: 156 | AI15: 10 | AJ15: 4616135872 | AM15: Fijo | AN15: 20.524145 | AO15: -100.81184 | AP15: 41974
A16: 6345492 | B16: ENVASADORAS DE AGUAS EN MEXICO S DE RL DE CV | C16: ENVASADORAS DE AGUAS EN MEXICO S DE RL DE CV | D16: 312112 | E16: Purificacion y embotellado de agua | F16: =VLOOKUP(E16,Sheet1!$B$2:$C$78,2,0) -> 0 | G16: 31 a 50 personas | H16: AVENIDA | I16: SUR 9 | J16: CALLE | K16: PONIENTE 7 | L16: AVENIDA | M16: MÃ‰XICO-JAPÃ“N | N16: AVENIDA | O16: TECNOLÃ“GICO | P16: 126 | T16: 0 | V16: COLONIA | W16: CIUDAD INDUSTRIAL | AA16: 38010 | AB16: 11 | AC16: GUANAJUATO | AD16: 7 | AE16: CELAYA | AF16: 1 | AG16: Celaya | AH16: 955 | AI16: 25 | AJ16: 4616118690 | AM16: Fijo | AN16: 20.550471 | AO16: -100.82112 | AP16: 40360
A17: 1356778 | B17: FÃBRICA DE ALIMENTOS SALADOS PARA ANIMALES | C17: NUBBA COMERCIALIZADORA, S.A. DE C.V. | D17: 311110 | E17: Elaboracion de alimentos para animales | F17: =VLOOKUP(E17,Sheet1!$B$2:$C$78,2,0) -> 0 | G17: 11 a 30 personas | H17: CARRETERA | I17: CELAYA-SALVATIERRA | J17: CAMINO | K17: NINGUNO | L17: PRIVADA | M17: NINGUNO | N17: VEREDA | O17: NINGUNO | P17: 0 | Q17: SN | V17: EJIDO | W17: MICHINELAS | AA17: 38140 | AB17: 11 | AC17: GUANAJUATO | AD17: 7 | AE17: CELAYA | AF17: 1 | AG17: Celaya | AH17: 1671 | AI17: 2 | AJ17: 4616121035 | AK17: RBNUT@PRODIGY.NET.MX | AM17: Fijo | AN17: 20.476809 | AO17: -100.80861 | AP17: 40360
A18: 1352691 | B18: FABRICA DE CAJETAS MEX CEL | C18: MEX C.E.L., S.A. DE C.V. | D18: 311340 | E18: Elaboracion de dulces, chicles y productos de confiteria que no sean de chocolate | F18: =VLOOKUP(E18,Sheet1!$B$2:$C$78,2,0) -> 0 | G18: 11 a 30 personas | H18: CALLE | I18: FRANCISCO I. MADERO | J18: CALLE | K18: 16 DE SEPTIEMBRE | L18: CALLE | M18: CHAPALA | N18: CALLE | O18: JOSÃ‰ MARÃA MORELOS | P18: 0 | Q18: SN | V18: COLONIA | W18: EL ZAPOTE | AA18: 38057 | AB18: 11 | AC18: GUANAJUATO | AD18: 7 | AE18: CELAYA | AF18: 1 | AG18: Celaya | AH18: 018A | AI18: 6 | AJ18: 4616132430 | AM18: Fijo | AN18: 20.522264 | AO18: -100.80441 | AP18: 40360
A19: 1356895 | B19: FÃBRICA DE PRODUCTOS LÃCTEOS QUECEL | D19: 311513 | E19: Elaboracion de derivados y fermentos lacteos | F19: =VLOOKUP(E19,Sheet1!$B$2:$C$78,2,0) -> 0 | G19: 11 a 30 personas | H19: CALLE | I19: VILLAGRÃN | J19: CAMINO | K19: CAMINO A JOFRE | L19: AVENIDA | M19: LÃZARO CÃRDENAS | N19: EJE VIAL | O19: JUAN PABLO II | P19: 302 | V19: COLONIA | W19: SANTA MARÃA | AA19: 38090 | AB19: 11 | AC19: GUANAJUATO | AD19: 7 | AE19: CELAYA | AF19: 1 | AG19: Celaya | AH19: 550 | AI19: 14 | AJ19: 4616167722 | AM19: Fijo | AN19: 20.497262 | AO19: -100.81319 | AP19: 40360
A20: 6204284 | B20: FRISOX, S.A. DE C.V. | D20: 315110 | E20: Fabricacion de calcetines y medias de tejido de punto | F20: =VLOOKUP(E20,Sheet1!$B$2:$C$78,2,0) -> 0 | G20: 31 a 50 personas | H20: CALLE | I20: PONIENTE 2 | K20: NORTE 9 | M20: NORTE 11 | N20: CALLE | O20: PONIENTE 4 | P20: 0 | Q20: SN | V20: COLONIA | W20: CIUDAD INDUSTRIAL | AA20: 38010 | AB20: 11 | AC20: GUANAJUATO | AD20: 7 | AE20: CELAYA | AF20: 1 | AG20: Celaya | AH20: 940 | AI20: 25 | AJ20: 14615983300 | AK20: COMPRAS@FRISOX.COM | AL20: WWW.FRISOX.COM | AM20: Fijo | AN20: 20.553649 | AO20: -100.81923 | AP20: 40360
A21: 6233229 | B21: GOCSA PLANTA CELAYA | C21: GEUSA DE OCCIDENTE SA DE CV | D21: 312111 | E21: Elaboracion de refrescos y otras bebidas no alcoholicas | F21: =VLOOKUP(E21,Sheet1!$B$2:$C$78,2,0) -> 0 | G21: 51 a 100 personas | H21: CARRETERA | I21: MIGUEL HIDALGO | J21: EJE VIAL | K21: NOR PONIENTE | L21: PROLONGACIÃ“N | M21: MIGUEL HIDALGO | N21: CALLE | O21: CONCEPCION BEISTEGUH | P21: 0 | Q21: SN | T21: 0 | V21: COLONIA | W21: LOS ALAMOS | AA21: 38024 | AB21: 11 | AC21: GUANAJUATO | AD21: 7 | AE21: CELAYA | AF21: 1 | AG21: Celaya | AH21: 724 | AI21: 1 | AM21: Fijo | AN21: 20.5194 | AO21: -100.84131 | AP21: 41974
A22: 6332875 | B22: GRUPO LAMESA SA DE CV | C22: GRUPO LAMESA SA DE CV | D22: 311512 | E22: Elaboracion de leche en polvo, condensada y evaporada | F22: =VLOOKUP(E22,Sheet1!$B$2:$C$78,2,0) -> 0 | G22: 101 a 250 personas | H22: AVENIDA | I22: MÃ‰XICO-JAPÃ“N | K22: NORTE SUR | L22: CALLE | M22: NORTE 3 | N22: CALLE | O22: PONIENTE 6 | P22: 206 | T22: 0 | V22: COLONIA | W22: CIUDAD INDUSTRIAL | AA22: 38010 | AB22: 11 | AC22: GUANAJUATO | AD22: 7 | AE22: CELAYA | AF22: 1 | AG22: Celaya | AH22: 940 | AI22: 28 | AJ22: 4616118717 | AK22: NZMFER01@YAHOO.COM.MX | AL22: WWW.GRUPOLAMESA.COM | AM22: Fijo | AN22: 20.550993 | AO22: -100.80469 | AP22: 40360
A23: 1253769 | B23: HIELO CELAYA | D23: 312113 | E23: Elaboracion de hielo | F23: =VLOOKUP(E23,Sheet1!$B$2:$C$78,2,0) -> 0 | G23: 11 a 30 personas | H23: AVENIDA | I23: MÃ‰XICO-JAPÃ“N | J23: CALLE | K23: NORTE 2 | L23: CALLE | M23: ORIENTE 2 | N23: AVENIDA | O23: MÃ‰XICO-JAPÃ“N | P23: 316 | V23: CIUDAD INDUSTRIAL | W23: INDUSTRIAL | AA23: 38001 | AB23: 11 | AC23: GUANAJUATO | AD23: 7 | AE23: CELAYA | AF23: 1 | AG23: Celaya | AH23: 1544 | AI23: 47 | AJ23: 4616133303 | AM23: Fijo | AN23: 20.550531 | AO23: -100.80026 | AP23: 41974
A24: 6334809 | B24: HIELO CRISTAL DE IRAPUATO SA DE CV | C24: HIELO CRISTAL DE IRAPUATO SA DE CV | D24: 312113 | E24: Elaboracion de hielo | F24: =VLOOKUP(E24,Sheet1!$B$2:$C$78,2,0) -> 0 | G24: 31 a 50 personas | H24: CARRETERA | I24: PANAMERICANA | K24: NINGUNO | M24: NINGUNO | O24: NINGUNO | P24: 0 | Q24: KILÃ“METRO 287 | T24: 0 | W24: NINGUNO | AA24: 38020 | AB24: 11 | AC24: GUANAJUATO | AD24: 7 | AE24: CELAYA | AF24: 461 | AG24: Ninguno [Hielera] | AH24: 29 | AI24: 800 | AJ24: 4616110093 | AM24: Fijo | AN24: 20.515278 | AO24: -100.90417 | AP24: 40360
A25: 6334808 | B25: HIELO CRISTAL DE IRAPUATO SA DE CV | C25: HIELO CRISTAL DE IRAPUATO SA DE CV | D25: 312113 | E25: Elaboracion de hielo | F25: =VLOOKUP(E25,Sheet1!$B$2:$C$78,2,0) -> 0 | G25: 31 a 50 personas | H25: AVENIDA | I25: CONSTITUYENTES | J25: PRIVADA | K25: ALHELÃES | L25: CALLE | M25: HENRRY DUNANT | N25: CALLE | O25: ALHELÃES | P25: 1700 | S25: 1 | T25: 0 | V25: COLONIA | W25: ROSALINDA II | X25: HOTEL | Y25: REAL DE MINAS | Z25: 1540 | AA25: 38060 | AB25: 11 | AC25: GUANAJUATO | AD25: 7 | AE25: CELAYA | AF25: 1 | AG25: Celaya | AH25: 1690 | AI25: 24 | AJ25: 4616148396 | AM25: Fijo | AN25: 20.51851 | AO25: -100.83971 | AP25: 40360
A26: 1248132 | B26: JC IMAGEN AUTOMOTRIZ, S.A. DE C.V. | C26: JC IMAGEN AUTOMOTRIZ, S.A. DE C.V. | D26: 314912 | E26: Confeccion de productos de textiles recubiertos y de materiales sucedaneos | F26: =VLOOKUP(E26,Sheet1!$B$2:$C$78,2,0) -> 0 | G26: 11 a 30 personas | H26: CALLE | I26: PEDRO VARGAS | J26: CALLE | K26: RUBÃ | L26: AVENIDA | M26: EL SAUZ | N26: CALLE | O26: JORGE NEGRETE | P26: 109 | V26: COLONIA | W26: IMPERIAL | AA26: 38020 | AB26: 11 | AC26: GUANAJUATO | AD26: 7 | AE26: CELAYA | AF26: 1 | AG26: Celaya | AH26: 1718 | AI26: 11 | AJ26: 4616161644 | AK26: JC_IMAGENAUTOTRIZ@PRODIGY.NET.MX | AM26: Fijo | AN26: 20.548588 | AO26: -100.8458 | AP26: 41974
A27: 1352661 | B27: KEUKA MÃ‰XICO | C27: KEUKA MÃ‰XICO, S.A. DE C.V. | D27: 315223 | E27: Confeccion en serie de uniformes | F27: =VLOOKUP(E27,Sheet1!$B$2:$C$78,2,0) -> 0 | G27: 11 a 30 personas | H27: CALLE | I27: FRANCISCO I. MADERO | K27: NINGUNO | L27: CALLE | M27: 16 DE SEPTIEMBRE | N27: CALLE | O27: JOSÃ‰ MARÃA MORELOS | P27: 0 | Q27: SN | V27: COLONIA | W27: CENTRO | AA27: 38000 | AB27: 11 | AC27: GUANAJUATO | AD27: 7 | AE27: CELAYA | AF27: 1 | AG27: Celaya | AH27: 018A | AI27: 5 | AJ27: 4616162681 | AM27: Fijo | AN27: 20.522219 | AO27: -100.80366 | AP27: 40360
A28: 1249127 | B28: MAQUILADORA SIN NOMBRE | D28: 315229 | E28: Confeccion en serie de otra ropa exterior de materiales textiles | F28: =VLOOKUP(E28,Sheet1!$B$2:$C$78,2,0) -> 0 | G28: 11 a 30 personas | H28: AVENIDA | I28: DEL SOL | J28: PRIVADA | K28: HACIENDA DE LOS AGUSTINOS | L28: CALLE | M28: FELIPE ÃNGELES | N28: AVENIDA | O28: DEL SOL | P28: 224 | W28: RINCÃ“N DE TAMAYO | AA28: 38150 | AB28: 11 | AC28: GUANAJUATO | AD28: 7 | AE28: CELAYA | AF28: 143 | AG28: Rincon de Tamayo | AH28: 917 | AI28: 1 | AM28: Fijo | AN28: 20.421909 | AO28: -100.76608 | AP28: 41974
A29: 1347113 | B29: MASERTEX | D29: 315229 | E29: Confeccion en serie de otra ropa exterior de materiales textiles | F29: =VLOOKUP(E29,Sheet1!$B$2:$C$78,2,0) -> 0 | G29: 11 a 30 personas | H29: CALLE | I29: PONIENTE 4 | J29: CALLE | K29: NORTE 3 | L29: AVENIDA | M29: NORTE 5 | N29: CALLE | O29: NINGUNO | P29: 0 | Q29: SN | V29: COLONIA | W29: CIUDAD INDUSTRIAL | AA29: 38010 | AB29: 11 | AC29: GUANAJUATO | AD29: 7 | AE29: CELAYA | AF29: 1 | AG29: Celaya | AH29: 940 | AI29: 39 | AJ29: 9616116511 | AK29: MASE.MARG@HOTMAIL.COM | AM29: Fijo | AN29: 20.554414 | AO29: -100.81249 | AP29: 40360
A30: 6330618 | B30: MOLINERA DE MEXICO SA DE CV | C30: MOLINERA DE MEXICO SA DE CV | D30: 311212 | E30: Elaboracion de harina de trigo | F30: =VLOOKUP(E30,Sheet1!$B$2:$C$78,2,0) -> 0 | G30: 101 a 250 personas | H30: AVENIDA | I30: 12 DE OCTUBRE | J30: CALLE | K30: LUIS ENRIQUE ERRO | L30: AVENIDA | M30: 12 DE OCTUBRE | N30: CALLE | O30: ANDRES QUINTANA ROO | P30: 0 | Q30: SN | T30: 0 | U30: SN | V30: COLONIA | W30: GIRASOLES | AA30: 38020 | AB30: 11 | AC30: GUANAJUATO | AD30: 7 | AE30: CELAYA | AF30: 1 | AG30: Celaya | AH30: 1065 | AI30: 26 | AJ30: 4616188470 | AL30: WWW.GRUMA.COM | AM30: Fijo | AN30: 20.520648 | AO30: -100.83807 | AP30: 40360
A31: 6330256 | B31: NUBBA COMERCIAL SA DE CV | C31: NUBBA COMERCIAL SA DE CV | D31: 311110 | E31: Elaboracion de alimentos para animales | F31: =VLOOKUP(E31,Sheet1!$B$2:$C$78,2,0) -> 0 | G31: 31 a 50 personas | H31: CALLE | I31: PASEO DE LOS CONSTITUYENTES | J31: CALLE | K31: DIVISIÃ“N DEL NORTE | L31: CALLE | M31: PASEO DE LOS CONSTITUYENTES | N31: CALLE | O31: LENACIA GÃ“MEZ | P31: 202 | T31: 0 | V31: COLONIA | W31: EL VERGEL | AA31: 38070 | AB31: 11 | AC31: GUANAJUATO | AD31: 7 | AE31: CELAYA | AF31: 1 | AG31: Celaya | AH31: 1224 | AI31: 26 | AJ31: 4616121035 | AK31: T.NAVA@RBNUT.COM | AM31: Fijo | AN31: 20.513467 | AO31: -100.8027 | AP31: 40360
A32: 1356160 | B32: PANADERÃA EL BEBE | D32: 311812 | E32: Panificacion tradicional | F32: =VLOOKUP(E32,Sheet1!$B$2:$C$78,2,0) -> 0 | G32: 11 a 30 personas | H32: PROLONGACIÃ“N | I32: DE GUANAJUATO | J32: CALLE | K32: PASEO DE LOS ÃLAMOS | L32: AVENIDA | M32: TRES GUERRAS | N32: CALLE | O32: JACARANDAS | P32: 6 | V32: COLONIA | W32: JARDINES DE CELAYA | AA32: 38080 | AB32: 11 | AC32: GUANAJUATO | AD32: 7 | AE32: CELAYA | AF32: 1 | AG32: Celaya | AH32: 809 | AI32: 1 | AJ32: 4616162893 | AM32: Fijo | AN32: 20.51475 | AO32: -100.792 | AP32: 40360
A33: 1353286 | B33: PANADERÃA EL RICO PAN | D33: 311812 | E33: Panificacion tradicional | F33: =VLOOKUP(E33,Sheet1!$B$2:$C$78,2,0) -> 0 | G33: 11 a 30 personas | H33: CALLE | I33: BRÃGIDA ÃLVAREZ | J33: CALLE | K33: MARÃA CHÃVEZ | L33: CALLE | M33: MARÃA VICENTA ELIZARRARAS | N33: AVENIDA | O33: BOULEVARD ADOLFO LÃ“PEZ MATEOS | P33: 136 | V33: COLONIA | W33: LAS INSURGENTES | AA33: 38080 | AB33: 11 | AC33: GUANAJUATO | AD33: 7 | AE33: CELAYA | AF33: 1 | AG33: Celaya | AH33: 1099 | AI33: 14 | AJ33: 4616127749 | AM33: Fijo | AN33: 20.520974 | AO33: -100.79581 | AP33: 40360
A34: 1348395 | B34: PANADERÃA EL TRIGAL | C34: PANADERÃA EL TRIGAL, S.A. DE C.V. | D34: 311812 | E34: Panificacion tradicional | F34: =VLOOKUP(E34,Sheet1!$B$2:$C$78,2,0) -> 0 | G34: 11 a 30 personas | H34: AVENIDA | I34: PROFESOR FRANCISCO JUÃREZ | J34: CALLE | K34: ALBINO GARCÃA | L34: CALLE | M34: MANUEL DOBLADO | N34: CALLE | O34: MARIANO ABASOLO | P34: 525 | V34: COLONIA | W34: TIERRAS NEGRAS | AA34: 38048 | AB34: 11 | AC34: GUANAJUATO | AD34: 7 | AE34: CELAYA | AF34: 1 | AG34: Celaya | AH34: 137 | AI34: 5 | AJ34: 4616147410 | AM34: Fijo | AN34: 20.525172 | AO34: -100.82602 | AP34: 40360
A35: 1347395 | B35: PANADERÃA SIN NOMBRE | D35: 311812 | E35: Panificacion tradicional | F35: =VLOOKUP(E35,Sheet1!$B$2:$C$78,2,0) -> 0 | G35: 11 a 30 personas | H35: CALLE | I35: MARIANO JIMÃ‰NEZ | J35: CALLE | K35: GENERALA ANTONIA NAVA DE CATALÃN | L35: CALLE | M35: MARIANO ABASOLO | N35: CALLE | O35: HERMENEGILDO GALEANA | P35: 0 | Q35: SN | V35: COLONIA | W35: MARIANO JIMÃ‰NEZ | AA35: 38048 | AB35: 11 | AC35: GUANAJUATO | AD35: 7 | AE35: CELAYA | AF35: 1 | AG35: Celaya | AH35: 103 | AI35: 30 | AJ35: 4611699146 | AM35: Fijo | AN35: 20.529105 | AO35: -100.82372 | AP35: 40360
A36: 6227834 | B36: PANAMCO MEXICO SA DE CV | C36: PANAMCO MEXICO SA DE CV | D36: 312111 | E36: Elaboracion de refrescos y otras bebidas no alcoholicas | F36: =VLOOKUP(E36,Sheet1!$B$2:$C$78,2,0) -> 0 | G36: 31 a 50 personas | H36: CARRETERA | I36: A QUERÃ‰TARO | J36: CALLE | K36: ADOLFO DE LA HUERTA | L36: CALLE | M36: ROSA BLANCA | N36: CALLE | O36: NINGUNO | P36: 0 | Q36: SN | T36: 0 | V36: COLONIA | W36: TRES GUERRAS | AA36: 38080 | AB36: 11 | AC36: GUANAJUATO | AD36: 7 | AE36: CELAYA | AF36: 1 | AG36: Celaya | AH36: 813 | AI36: 4 | AJ36: 4611595937 | AM36: Fijo | AN36: 20.515915 | AO36: -100.78321 | AP36: 40360
A37: 6331279 | B37: PANAMCO MEXICO SA DE CV | C37: PANAMCO MEXICO SA DE CV | D37: 312111 | E37: Elaboracion de refrescos y otras bebidas no alcoholicas | F37: =VLOOKUP(E37,Sheet1!$B$2:$C$78,2,0) -> 0 | G37: 31 a 50 personas | H37: CARRETERA | I37: A QUERÃ‰TARO | J37: CALLE | K37: MIGUEL ALEMÃN | L37: CALLE | M37: PRESA BLANCA | N37: CALLEJÃ“N | O37: 3 GUERRAS | P37: 0 | Q37: KILÃ“METRO 370 | T37: 0 | V37: COLONIA | W37: TRES GUERRAS | AA37: 38130 | AB37: 11 | AC37: GUANAJUATO | AD37: 7 | AE37: CELAYA | AF37: 1 | AG37: Celaya | AH37: 813 | AI37: 4 | AM37: Fijo | AN37: 20.515914 | AO37: -100.7832 | AP37: 40360
A38: 1348296 | B38: PANIFICADORA CUELLAR EL FÃ‰NIX | C38: PANIFICADORA CUELLAR, S.A. DE C.V. | D38: 311812 | E38: Panificacion tradicional | F38: =VLOOKUP(E38,Sheet1!$B$2:$C$78,2,0) -> 0 | G38: 11 a 30 personas | H38: CALLE | I38: MANUEL DOBLADO | J38: CALLE | K38: LEANDRO VALLE | L38: CALLE | M38: MARIANO ABASOLO | N38: CALLE | O38: ANDRÃ‰S QUINTANA ROO | P38: 426 | V38: COLONIA | W38: CENTRO | AA38: 38000 | AB38: 11 | AC38: GUANAJUATO | AD38: 7 | AE38: CELAYA | AF38: 1 | AG38: Celaya | AH38: 137 | AI38: 2 | AJ38: 4616120534 | AM38: Fijo | AN38: 20.523212 | AO38: -100.82157 | AP38: 40360
A39: 1349095 | B39: PANIFICADORA EL SOL | C39: PANIFICADORA EL SOL DE IRAPUATO, S.A. DE C.V. | D39: 311812 | E39: Panificacion tradicional | F39: =VLOOKUP(E39,Sheet1!$B$2:$C$78,2,0) -> 0 | G39: 11 a 30 personas | H39: CALLE | I39: COLUNGA GUERRERO | J39: CALLE | K39: CORREGIDORA | L39: AVENIDA | M39: LICENCIADO BENITO JUÃREZ | N39: AVENIDA | O39: MIGUEL HIDALGO | P39: 102 | V39: COLONIA | W39: CENTRO | AA39: 38000 | AB39: 11 | AC39: GUANAJUATO | AD39: 7 | AE39: CELAYA | AF39: 1 | AG39: Celaya | AH39: 156 | AI39: 12 | AJ39: 4616138112 | AM39: Fijo | AN39: 20.522157 | AO39: -100.81464 | AP39: 40360
A40: 1348886 | B40: PASTELERÃA LAS DÃAZ BARRIGA, S.A. DE C.V. | C40: PASTELERÃA LAS DÃAZ BARRIGA, S.A. DE C.V. | D40: 311812 | E40: Panificacion tradicional | F40: =VLOOKUP(E40,Sheet1!$B$2:$C$78,2,0) -> 0 | G40: 11 a 30 personas | H40: CALLE | I40: ÃLVARO OBREGÃ“N | J40: PRIVADA | K40: ÃLVARO OBREGÃ“N | L40: CALLE | M40: AGUILAR Y MAYA | N40: AVENIDA | O40: LICENCIADO BENITO JUÃREZ | P40: 344 | Q40: C | V40: COLONIA | W40: ALAMEDA | AA40: 38050 | AB40: 11 | AC40: GUANAJUATO | AD40: 7 | AE40: CELAYA | AF40: 1 | AG40: Celaya | AH40: 156 | AI40: 25 | AJ40: 4616127663 | AK40: PASTELERIADIAZBARRIGA@YAHOO.COM.MX | AM40: Fijo | AN40: 20.528089 | AO40: -100.81314 | AP40: 40360
...

Sheet Sheet1
B1: CON | C1: SN
B2: Purificacion y embotellado de agua | C2: 0
B3: Conservacion de frutas y verduras por procesos distintos a la congelacion y la deshidratacion | C3: 0
B4: Elaboracion de alimentos para animales | C4: 0
B5: Elaboracion de dulces, chicles y productos de confiteria que no sean de chocolate | C5: 0
B6: Confeccion en serie de otra ropa exterior de materiales textiles | C6: 0
B7: Confeccion en serie de uniformes | C7: 0
B8: Elaboracion de aceites y grasas vegetales comestibles | C8: 0
B9: Fabricacion de ropa exterior de tejido de punto | C9: 0
B10: Elaboracion de botanas | C10: 0
B11: Panificacion tradicional | C11: 0
B12: Preparacion de embutidos y otras conservas de carne de ganado, aves y otros animales comestibles | C12: 0
B13: Elaboracion de derivados y fermentos lacteos | C13: 0
... B78: Fabricacion de otra maquinaria y equipo para la industria en general | C78: 0
